Workbook
Name ___NSO2: {"'Sheet1'!$L$16"}
Name __a1: {"'Sheet1'!$L$16"}
Name __h1: {"'Sheet1'!$L$16"}
Name __hu1: {"'Sheet1'!$L$16"}
Name __hu2: {"'Sheet1'!$L$16"}
Name __hu5: {"'Sheet1'!$L$16"}
Name __hu6: {"'Sheet1'!$L$16"}
Name __IntlFixup: TRUE
Name __NSO2: {"'Sheet1'!$L$16"}
Name __PA3: {"'Sheet1'!$L$16"}
Name _a1: {"'Sheet1'!$L$16"}
Name _a2: {"'Sheet1'!$L$16"}
Name _CN1: {"'Sheet1'!$L$16"}
Name _cn3: {"'Sheet1'!$L$16"}
Name _d1500: {"'Sheet1'!$L$16"}
Name _GD3: {"'Sheet1'!$L$16"}
Name _Goi8: {"'Sheet1'!$L$16"}
Name _h1: {"'Sheet1'!$L$16"}
Name _hu1: {"'Sheet1'!$L$16"}
Name _hu2: {"'Sheet1'!$L$16"}
Name _hu5: {"'Sheet1'!$L$16"}
Name _hu6: {"'Sheet1'!$L$16"}
Name _NSO2: {"'Sheet1'!$L$16"}
Name _Order1: 255
Name _Order2: 255
Name _PA3: {"'Sheet1'!$L$16"}
Name _Regression_Int: 1
Name _T2: {"'Sheet1'!$L$16"}
Name aaafff: {"'장비'!$A$3:$M$12"}
Name AccessDatabase: "D:\_genkou\excel97\sample\支店集計作業\本社合計2.mdb"
Name ADITION: {"'장비'!$A$3:$M$12"}
Name agfg: {"'장비'!$A$3:$M$12"}
Name anscount: 1
Name AS2DocOpenMode: "AS2DocumentEdit"
Name ATGT: {"'Sheet1'!$L$16"}
Name bc: {"'Sheet1'!$L$16"}
Name BCTQ: {"'Sheet1'!$L$16"}
Name btl: {"'Sheet1'!$L$16"}
Name chitietbgiang2: {"'Sheet1'!$L$16"}
Name chuyen: {"'Sheet1'!$L$16"}
Name civil2: {"'장비'!$A$3:$M$12"}
Name cn2a: {"'Sheet1'!$L$16"}
Name CON: {"'Sheet1'!$L$16"}
Name concrete: {"'Sheet1'!$L$16"}
Name CTCT1: {"'Sheet1'!$L$16"}
Name dddf: {"'장비'!$A$3:$M$12"}
Name dfaf: {"'장비'!$A$3:$M$12"}
Name dfdf: {"'장비'!$A$3:$M$12"}
Name DIAMOND: {"'장비'!$A$3:$M$12"}
Name ert: {"'장비'!$A$3:$M$12"}
Name erty: {"'장비'!$A$3:$M$12"}
Name EWRWE: {"'장비'!$A$3:$M$12"}
Name ewrweq: {"'장비'!$A$3:$M$12"}
Name fffffffg: {"'장비'!$A$3:$M$12"}
Name ffgfg: {"'장비'!$A$3:$M$12"}
Name FIRST: {"'Sheet1'!$L$16"}
Name FORMWORK: {"'Sheet1'!$L$16"}
Name ga: {"'Sheet1'!$L$16"}
Name gggg: {"'장비'!$A$3:$M$12"}
Name gh: {"'Sheet1'!$L$16"}

Sheet 1.Báo giá
C1: CÔNG TY TNHH CÔNG NGHỆ CÔNG NGHIỆP PHÚ SƠN
C2: Địa chỉ: Lô 7 CN5, Cụm công nghiệp Ngọc Hồi, xã Ngọc Hồi, Thành phố Hà Nội
C3: MST: 0104113174 | D3: https://panelphuson.vn | H3: https://javta.vn
A4: BẢNG BÁO GIÁ SẢN PHẨM - KIÊM XÁC NHẬN ĐƠN HÀNG
A6: Kính gửi: Công ty CP Giải pháp Cách nhiệt Việt Nam | H6: Số:090626.01 Ngày: 09/06/26
A7: Địa chỉ: Lô 7 CN6 - Cụm công nghiệp Ngọc Hồi | H7: Hiệu lực đến: 14/06/2026
A8: Người liên hệ: | C8: Mr Thành - 0982476556 | H8: NVKD: | I8: Mr Long - 0978349917
A9: Cảm ơn Quý khách hàng đã quan tâm tới sản phẩm do Công ty TNHH Công nghệ Công nghiệp Phú Sơn sản xuất. Chúng tôi xin gửi Báo giá sản phẩm theo yêu cầu Quý khách đã cung cấp với nội dung như sau:
A10: TT | B10: Tên sản phẩm/Quy cách | D10: Đơn vị | E10: Chiều rộng | F10: Chiều dài | G10: Số tấm | H10: Khối lượng | I10: Đơn giá (VNĐ) | J10: Thành tiền (VNĐ)
A11: I. | B11: PANEL PUR VÁCH TRONG (TÔN + PU + TÔN): * Mặt thứ nhất: Tôn nền Kamazn, dày 0,50±0,04mm, AZM100 màu KM W02. * Lớp giữa: PUR dày 100±2mm, tỷ trọng 45±3kg/m3. * Mặt thứ hai: Tôn nền Kamazn, dày 0,40±0,04mm, AZM50 màu KM W01. * Hai mặt tôn phẳng hoặc cán gân tăng cứng. Khổ hiệu dụng/khổ sản phẩm: 1.130/1.152 mm. Có dán nilong chống trầy xước. Tính m2 = chiều dài(m) x số tấm x 1,13
B12: Cộng nhóm I - chưa VAT 8% | G12: =SUM(G13:G14) -> 34 | H12: =SUM(H13:H14) -> 198.88 | I12: 452000 | J12: =I12*H12 -> 89893760
A13: 1 | B13: Tấm số 1 | D13: m2 | E13: 1.13 | F13: 5 | G13: 22 | H13: =G13*F13*E13 -> 124.3 | I13: =$I$12 -> 452000 | J13: =I13*H13 -> 56183600
A14: 2 | B14: Tấm số 2 | D14: m2 | E14: 1.13 | F14: 5.5 | G14: 12 | H14: =G14*F14*E14 -> 74.58 | I14: =$I$12 -> 452000 | J14: =I14*H14 -> 33710160
A15: II. | B15: TẤM LỢP PU 5 SÓNG (TÔN + PU + TÔN): * Mặt trên: Tôn nền Kamazn, dày 0,45±0,04mm, AZM50, màu KM W02 * Lớp giữa: PU chống cháy lan B2, dày 50±2mm, tỷ trọng 35±3kg/m3 * Mặt dưới: Tôn nền liên doanh dày 0,23±0,04mm, có hèm chống hở, màu trắng. * Chiều cao sóng dương 32±2mm. Khổ hiệu dụng/khổ sản phẩm: 1.000/1.080mm. Tính m2 = chiều dài(m) x số tấm x 1,08
B16: Cộng nhóm II - chưa VAT 10% | G16: =SUM(G17:G18) -> 16 | H16: =SUM(H17:H19) -> 86.784 | I16: 162000 | J16: =H16*I16 -> 14059008
A17: 1 | B17: Tấm số 1 | D17: m2 | E17: 1.08 | F17: 6.2 | G17: 8 | H17: =G17*F17*E17 -> 53.568 | I17: =$I$16 -> 162000 | J17: =I17*H17 -> 8678016
A18: 2 | B18: Tấm số 2 | D18: m2 | E18: 1.08 | F18: 3.15 | G18: 8 | H18: =G18*F18*E18 -> 27.216 | I18: =$I$16 -> 162000 | J18: =I18*H18 -> 4408992
A19: 3 | B19: Hao phí đơn hàng dưới 100m2 | D19: m2 | H19: 6 | I19: =$I$16 -> 162000 | J19: =I19*H19 -> 972000
A20: III. | B20: PHỤ KIỆN VÁCH: Không gấp mép * Tôn nền Kamaz, dày 0,45±0,04mm, AZM50, màu theo vách
B21: Cộng nhóm II - chưa VAT 10% | G21: =SUM(G22:G23) -> 21 | H21: =SUM(H22:H23) -> 84 | J21: =SUM(J22:J23) -> 4080000
A22: 1 | B22: Khổ 400mm | D22: m | E22: 0.4 | F22: 4 | G22: 15 | H22: =G22*F22 -> 60 | I22: 42000 | J22: =I22*H22 -> 2520000
A23: 2 | B23: Khổ 600mm | D23: m | E23: 0.6 | F23: 4 | G23: 6 | H23: =G23*F23 -> 24 | I23: 65000 | J23: =I23*H23 -> 1560000
A24: A | B24: Tổng giá trị hàng hóa chưa VAT: | J24: =J21+J16+J12 -> 108032768
A25: B | B25: Tiền VAT 8% | J25: =(J12)*8% -> 7191500.8
A26: C | B26: Tiền VAT 10% | J26: =(J21+J16)*10% -> 1813900.8
A27: D | B27: Tổng giá trị thanh toán, đã bao gồm VAT: D = (A)+(B)+(C) | J27: =J26+J25+J24 -> 1.1703817e+08
A28: Bằng chữ: | C28: Một trăm mười bảy triệu, không trăm ba mươi tám nghìn, một trăm bảy mươi đồng ./.
A29: Ghi chú:
A30: 1. Đơn giá đã bao gồm VAT: Tấm lợp PU, EPS, RW, GW, Vận chuyển thuế 8%; Phụ kiện tôn, inox, 1 lớp thuế 10%
A31: 2. Dung sai kích thước chiều dài ±5mm, chiều rộng ±4mm | E31: 3. Dung sai độ dày PU/EPS ±2mm, tấm lấy sáng ±0,2mm.
A32: 4. Tỷ trọng PU ±3kg/m3, tỷ trọng EPS ±1kg/m3 | E32: 5. Dung sai độ dày tôn ±0,03÷0,04mm
A33: 6. Giá trên chưa bao gồm vận chuyển. | K33: 6. này có chỗ xổ để chọn: Giá trên chưa có bao gồm vận chuyển HOẶC Giá trên đã bao gồm vận chuyển
A34: Phương thức thanh toán:
A35: - Lần 1: Bên mua đặt cọc sản xuất tương ứng 50% giá trị đơn hàng ngay sau khi xác nhận đơn đặt hàng.
A36: - Lần 2: Thanh toán 50% giá trị còn lại và lấy phát sinh (nếu có) trước khi xuất xưởng của bên bán
A37: Thông tin tài khoản nhận đơn đặt hàng:
A38: Tên TK: Công ty TNHH Công Nghệ Công Nghiệp Phú Sơn.
A39: Số TK: 7999989399 mở tại ngân hàng TMCP Quân Đội - CN Hai Bà Trưng
B40: ĐẠI DIỆN BÊN MUA | I40: ĐẠI DIỆN BÊN BÁN
I41: =I8 -> Mr Long - 0978349917
...

Sheet 2. Lệnh sản xuất nội bộ 
C1: CÔNG TY TNHH CÔNG NGHỆ CÔNG NGHIỆP PHÚ SƠN | J1: =$L$1&"."&$L$2 -> . | V1: =$J$28 -> 989399 | W1: =RIGHT("000000000000"&ROUND(V1,0),12) -> 000000989399 | X1: 1 | Y1: 2 | Z1: 3 | AA1: 4 | AB1: 5 | AC1: 6 | AD1: 7 | AE1: 8 | AF1: 9 | AG1: 10 | AH1: 11 | AI1: 12
C2: Địa chỉ: Lô 7 CN5, Cụm công nghiệp Ngọc Hồi, xã Ngọc Hồi, Thành phố Hà Nội | X2: =VALUE(MID(W1,X1,1)) -> 0 | Y2: =VALUE(MID(W1,Y1,1)) -> 0 | Z2: =VALUE(MID(W1,Z1,1)) -> 0 | AA2: =VALUE(MID(W1,AA1,1)) -> 0 | AB2: =VALUE(MID(W1,AB1,1)) -> 0 | AC2: =VALUE(MID(W1,AC1,1)) -> 0 | AD2: =VALUE(MID(W1,AD1,1)) -> 9 | AE2: =VALUE(MID(W1,AE1,1)) -> 8 | AF2: =VALUE(MID(W1,AF1,1)) -> 9 | AG2: =VALUE(MID(W1,AG1,1)) -> 3 | AH2: =VALUE(MID(W1,AH1,1)) -> 9 | AI2: =VALUE(MID(W1,AI1,1)) -> 9
C3: MST: 0104113174 | E3: https://panelphuson.vn | H3: https://javta.vn | X3: =SUM(X2) -> 0 | Y3: =SUM(X2:Y2) -> 0 | Z3: =SUM(X2:Z2) -> 0 | AA3: =SUM(AA2) -> 0 | AB3: =SUM(AA2:AB2) -> 0 | AC3: =SUM(AA2:AC2) -> 0 | AD3: =SUM(AD2) -> 9 | AE3: =SUM(AD2:AE2) -> 17 | AF3: =SUM(AD2:AF2) -> 26 | AG3: =SUM(AG2) -> 3 | AH3: =SUM(AG2:AH2) -> 12 | AI3: =SUM(AG2:AI2) -> 21
C4: Số lệnh sản xuất: | D4: 6508 | E4: /PS | H4: Thời gian gửi: | I4: =NOW() -> 46182.935 | X4: =IF(X2=0,"",CHOOSE(X2,"một","hai","ba","bốn","năm","sáu","bảy","tám","chín")) | Y4: =IF(Y2=0,IF(AND(X2<>0,Z2<>0),"lẻ",""),CHOOSE(Y2,"mười","hai","ba","bốn","năm","sáu","bảy","tám","chín")) | Z4: =IF(Z2=0,"",CHOOSE(Z2,IF(Y2>1,"mốt","một"),"hai","ba","bốn",IF(Y2=0,"năm","lăm"),"sáu","bảy","tám","chín")) | AA4: =IF(AA2=0,"",CHOOSE(AA2,"một","hai","ba","bốn","năm","sáu","bảy","tám","chín")) | AB4: =IF(AB2=0,IF(AND(AA2<>0,AC2<>0),"lẻ",""),CHOOSE(AB2,"mười","hai","ba","bốn","năm","sáu","bảy","tám","chín")) | AC4: =IF(AC2=0,"",CHOOSE(AC2,IF(AB2>1,"mốt","một"),"hai","ba","bốn",IF(AB2=0,"năm","lăm"),"sáu","bảy","tám","chín")) | AD4: =IF(AD2=0,"",CHOOSE(AD2,"một","hai","ba","bốn","năm","sáu","bảy","tám","chín")) -> chín | AE4: =IF(AE2=0,IF(AND(AD2<>0,AF2<>0),"lẻ",""),CHOOSE(AE2,"mười","hai","ba","bốn","năm","sáu","bảy","tám","chín")) -> tám | AF4: =IF(AF2=0,"",CHOOSE(AF2,IF(AE2>1,"mốt","một"),"hai","ba","bốn",IF(AE2=0,"năm","lăm"),"sáu","bảy","tám","chín")) -> chín | AG4: =IF(AG2=0,"",CHOOSE(AG2,"một","hai","ba","bốn","năm","sáu","bảy","tám","chín")) -> ba | AH4: =IF(AH2=0,IF(AND(AG2<>0,AI2<>0),"lẻ",""),CHOOSE(AH2,"mười","hai","ba","bốn","năm","sáu","bảy","tám","chín")) -> chín | AI4: =IF(AI2=0,"",CHOOSE(AI2,IF(AH2>1,"mốt","một"),"hai","ba","bốn",IF(AH2=0,"năm","lăm"),"sáu","bảy","tám","chín")) -> chín
C5: LỆNH SẢN XUẤT | L5: Lấy số từ hệ thống kế toán | X5: =IF(X2=0,"","trăm") | Y5: =IF(Y2=0,"",IF(Y2=1,"","mươi")) | Z5: =IF(AND(Z2=0,Z3=0),"","tỷ,") | AA5: =IF(AA2=0,"","trăm") | AB5: =IF(AB2=0,"",IF(AB2=1,"","mươi")) | AC5: =IF(AND(AC2=0,AC3=0),"","triệu,") | AD5: =IF(AD2=0,"","trăm") -> trăm | AE5: =IF(AE2=0,"",IF(AE2=1,"","mươi")) -> mươi | AF5: =IF(AND(AF2=0,AF3=0),"","ngàn,") -> ngàn, | AG5: =IF(AG2=0,"","trăm") -> trăm | AH5: =IF(AH2=0,"",IF(AH2=1,"","mươi")) -> mươi
A6: Khách hàng: | C6: Công ty CP Giải pháp Cách nhiệt Việt Nam | I6: NVKD: Mr Long | L6: Ví dụ 6508PS | W6: =UPPER(LEFT(TRIM(IF(V1=0,"không đồng.",X4&" "&X5&" "&Y4&" "&Y5&" "&Z4&" "&Z5&" "&AA4&" "&AA5&" "&AB4&" "&AB5&" "&AC4&" "&AC5&" "&AD4&" "&AD5&" "&AE4&" "&AE5&" "&AF4&" "&AF5&" "&AG4&" "&AG5&" "&AH4&" "&AH5&" "&AI4&" "&AI5)),1))&RIGHT(TRIM(IF(V1=0,"không đồng.",X4&" "&X5&" "&Y4&" "&Y5&" "&Z4&" "&Z5&" "&AA4&" "&AA5&" "&AB4&" "&AB5&" "&AC4&" "&AC5&" "&AD4&" "&AD5&" "&AE4&" "&AE5&" "&AF4&" "&AF5&" "&AG4&" "&AG5&" "&AH4&" "&AH5&" "&AI4&" "&AI5)),LEN(TRIM(IF(V1=0,"không đồng.",X4&" "&X5&" "&Y4&" "&Y5&" "&Z4&" "&Z5&" "&AA4&" "&AA5&" "&AB4&" "&AB5&" "&AC4&" "&AC5&" "&AD4&" "&AD5&" "&AE4&" "&AE5&" "&AF4&" "&AF5&" "&AG4&" "&AG5&" "&AH4&" "&AH5&" "&AI4&" "&AI5)))-1) -> Chín trăm tám mươi chín ngàn, ba trăm chín mươi chín
A7: Liên hệ: | C7: Mr Thành - 0982476556 | I7: Điện thoại: 0978349917 | W7: =""&$W$6&" đồng ./." -> Chín trăm tám mươi chín ngàn, ba trăm chín mươi chín đồng ./.
A8: * NỘI DUNG YÊU CẦU SẢN XUẤT:
A9: TT | B9: Tên sản phẩm/Quy cách | D9: Đơn vị | E9: Chiều rộng | F9: Chiều dài | G9: Số tấm | H9: Khối lượng | I9: Đơn giá (VNĐ) | J9: Thành tiền (VNĐ)
A10: I. | B10: PANEL PUR VÁCH TRONG (TÔN + PU + TÔN): * Mặt thứ nhất: Tôn nền Kamazn, dày 0,50±0,04mm, AZM100 màu KM W02. * Lớp giữa: PUR dày 100±2mm, tỷ trọng 45±3kg/m3. * Mặt thứ hai: Tôn nền Kamazn, dày 0,40±0,04mm, AZM50 màu KM W01. * Hai mặt tôn phẳng hoặc cán gân tăng cứng. Khổ hiệu dụng/khổ sản phẩm: 1.130/1.152 mm. Có dán nilong chống trầy xước. Tính m2 = chiều dài(m) x số tấm x 1,13
B11: Cộng nhóm I - chưa VAT 8% | G11: =SUM(G12:G13) -> 34 | H11: =SUM(H12:H13) -> 198.88 | I11: 452000 | J11: =I11*H11 -> 89893760
A12: 1 | B12: Tấm số 1 | D12: m2 | E12: 1.13 | F12: 5 | G12: 22 | H12: =G12*F12*E12 -> 124.3 | I12: =$I$12 -> 452000 | J12: =I12*H12 -> 56183600
A13: 2 | B13: Tấm số 2 | D13: m2 | E13: 1.13 | F13: 5.5 | G13: 12 | H13: =G13*F13*E13 -> 74.58 | I13: =$I$12 -> 452000 | J13: =I13*H13 -> 33710160
A14: II. | B14: TẤM LỢP PU 5 SÓNG (TÔN + PU + TÔN): * Mặt trên: Tôn nền Kamazn, dày 0,45±0,04mm, AZM50, màu KM W02 * Lớp giữa: PU chống cháy lan B2, dày 50±2mm, tỷ trọng 35±3kg/m3 * Mặt dưới: Tôn nền liên doanh dày 0,23±0,04mm, có hèm chống hở, màu trắng. * Chiều cao sóng dương 32±2mm. Khổ hiệu dụng/khổ sản phẩm: 1.000/1.080mm. Tính m2 = chiều dài(m) x số tấm x 1,08
B15: Cộng nhóm II - chưa VAT 10% | G15: =SUM(G16:G17) -> 16 | H15: =SUM(H16:H18) -> 86.784 | I15: 162000 | J15: =H15*I15 -> 14059008
A16: 1 | B16: Tấm số 1 | D16: m2 | E16: 1.08 | F16: 6.2 | G16: 8 | H16: =G16*F16*E16 -> 53.568 | I16: =$I$16 -> 162000 | J16: =I16*H16 -> 8678016
A17: 2 | B17: Tấm số 2 | D17: m2 | E17: 1.08 | F17: 3.15 | G17: 8 | H17: =G17*F17*E17 -> 27.216 | I17: =$I$16 -> 162000 | J17: =I17*H17 -> 4408992
A18: 3 | B18: Hao phí đơn hàng dưới 100m2 | D18: m2 | H18: 6 | I18: =$I$16 -> 162000 | J18: =I18*H18 -> 972000
A19: III. | B19: PHỤ KIỆN VÁCH: Không gấp mép * Tôn nền Kamaz, dày 0,45±0,04mm, AZM50, màu theo vách
B20: Cộng nhóm II - chưa VAT 10% | G20: =SUM(G21:G22) -> 21 | H20: =SUM(H21:H22) -> 84 | J20: =SUM(J21:J22) -> 4080000
A21: 1 | B21: Khổ 400mm | D21: m | E21: 0.4 | F21: 4 | G21: 15 | H21: =G21*F21 -> 60 | I21: 42000 | J21: =I21*H21 -> 2520000
A22: 2 | B22: Khổ 600mm | D22: m | E22: 0.6 | F22: 4 | G22: 6 | H22: =G22*F22 -> 24 | I22: 65000 | J22: =I22*H22 -> 1560000
A23: A | B23: Tổng giá trị hàng hóa chưa VAT: | J23: =J20+J15+J11 -> 108032768
A24: B | B24: Tiền VAT 8% | J24: =(J11)*8% -> 7191500.8
A25: C | B25: Tiền VAT 10% | J25: =(J20+J15)*10% -> 1813900.8
A26: D | B26: Tổng giá trị thanh toán, đã bao gồm VAT: D = (A)+(B)+(C) | J26: =J25+J24+J23 -> 1.1703817e+08
A27: Bằng chữ: | C27: Một trăm mười bảy triệu, không trăm ba mươi tám nghìn, một trăm bảy mươi đồng ./.
A28: Ghi chú: | J28: 989399
A29: 1. Đơn giá đã bao gồm VAT: Tấm lợp PU, EPS, RW, GW, Vận chuyển thuế 8%; Phụ kiện tôn, inox, 1 lớp thuế 10% | K29: Giống bên báo giá
A30: 2. Dung sai kích thước chiều dài ±5mm, chiều rộng ±4mm | E30: 3. Dung sai độ dày PU/EPS ±2mm, tấm lấy sáng ±0,2mm.
A31: 4. Tỷ trọng PU ±3kg/m3, tỷ trọng EPS ±1kg/m3 | E31: 5. Dung sai độ dày tôn ±0,03÷0,04mm
A32: ='1.Báo giá'!A33 -> 6. Giá trên chưa bao gồm vận chuyển.
A33: ** ĐIỀU KIỆN GIAO HÀNG VÀ THANH TOÁN
A34: 1.Nghiệm thu: | C34: tại Nhà máy Phú Sơn | E34: 2. Ngày nghiệm thu: | H34: 46188
A35: 3.Vận chuyển: | C35: Khách hàng tự vận chuyển. | E35: 4. Thông tin sản phẩm: | H35: Không in thông tin nhà máy
A36: 5. Phiếu giao: | C36: Phiếu xuất kho của Khách hàng. | E36: 6. Thời gian giao hàng: | H36: 46190
A37: 7. Người nhận: | C37: Mr Thuyết - 0955123654 | K37: Hoặc tên + Số điện thoại của người trên công trình
A38: 8. Địa điểm: | C38: Lô 4 CN6 - Khu công nghiệp Sông Công II - Thái Nguyên
A39: 9.Thanh toán: | C39: Theo Hợp đồng Kinh tế
A40: 10. Ghi chú: | C40: Lái xe chú ý, để khách kiểm tra hàng trên xe, đợi Kinh doanh báo mới cho hạ hàng.
...

Sheet 3. Lệnh sản xuất kiêm PXK
C1: CÔNG TY TNHH CÔNG NGHỆ CÔNG NGHIỆP PHÚ SƠN
C2: Địa chỉ: Lô 7 CN5, Cụm công nghiệp Ngọc Hồi, xã Ngọc Hồi, Thành phố Hà Nội
C3: MST: 0104113174 https://panelphuson.vn https://javta.vn
A4: LỆNH SẢN XUẤT KIÊM PHIẾU XUẤT KHO
C5: =" Ngày "&DAY(TODAY())&" tháng "& MONTH(TODAY())&" năm " &YEAR(TODAY()) -> Ngày 9 tháng 6 năm 2026 | G5: Số: | H5: ='2. Lệnh sản xuất nội bộ '!$D$4&"/PS" -> 6508/PS
A6: Khách hàng: | C6: ='2. Lệnh sản xuất nội bộ '!C6:H6 -> Công ty CP Giải pháp Cách nhiệt Việt Nam
A7: Địa chỉ: | C7: Lô 7 CN6 - Cụm công nghiệp Ngọc Hồi
A8: Thời gian giao: | C8: ='2. Lệnh sản xuất nội bộ '!H36 -> 46190 | D8: Người nhận hàng: | G8: ='2. Lệnh sản xuất nội bộ '!C37 -> Mr Thuyết - 0955123654
A9: Giao hàng tại: | C9: ='2. Lệnh sản xuất nội bộ '!C38 -> Lô 4 CN6 - Khu công nghiệp Sông Công II - Thái Nguyên
A10: Nhân viên KD: | C10: ='1.Báo giá'!I8 -> Mr Long - 0978349917
A12: TT | B12: Tên sản phẩm/Quy cách | D12: Đơn vị | E12: Chiều rộng | F12: Chiều dài | G12: Số tấm | H12: Khối lượng | I12: Đơn giá (VNĐ) | J12: Thành tiền (VNĐ)
A13: I. | B13: PANEL PUR VÁCH TRONG (TÔN + PU + TÔN): * Mặt thứ nhất: Tôn nền Kamazn, dày 0,50±0,04mm, AZM100 màu KM W02. * Lớp giữa: PUR dày 100±2mm, tỷ trọng 45±3kg/m3. * Mặt thứ hai: Tôn nền Kamazn, dày 0,40±0,04mm, AZM50 màu KM W01. * Hai mặt tôn phẳng hoặc cán gân tăng cứng. Khổ hiệu dụng/khổ sản phẩm: 1.130/1.152 mm. Có dán nilong chống trầy xước. Tính m2 = chiều dài(m) x số tấm x 1,13
G14: =SUM(G15:G16) -> 34 | H14: =SUM(H15:H16) -> 198.88 | I14: 452000 | J14: =I14*H14 -> 89893760
A15: 1 | B15: Tấm số 1 | D15: m2 | E15: 1.13 | F15: 5 | G15: 22 | H15: =G15*F15*E15 -> 124.3 | I15: =$I$12 -> Đơn giá (VNĐ) | J15: =I15*H15 -> #VALUE!
A16: 2 | B16: Tấm số 2 | D16: m2 | E16: 1.13 | F16: 5.5 | G16: 12 | H16: =G16*F16*E16 -> 74.58 | I16: =$I$12 -> Đơn giá (VNĐ) | J16: =I16*H16 -> #VALUE!
A17: II. | B17: TẤM LỢP PU 5 SÓNG (TÔN + PU + TÔN): * Mặt trên: Tôn nền Kamazn, dày 0,45±0,04mm, AZM50, màu KM W02 * Lớp giữa: PU chống cháy lan B2, dày 50±2mm, tỷ trọng 35±3kg/m3 * Mặt dưới: Tôn nền liên doanh dày 0,23±0,04mm, có hèm chống hở, màu trắng. * Chiều cao sóng dương 32±2mm. Khổ hiệu dụng/khổ sản phẩm: 1.000/1.080mm. Tính m2 = chiều dài(m) x số tấm x 1,08
G18: =SUM(G19:G20) -> 16 | H18: =SUM(H19:H21) -> 86.784 | I18: 162000 | J18: =H18*I18 -> 14059008
A19: 1 | B19: Tấm số 1 | D19: m2 | E19: 1.08 | F19: 6.2 | G19: 8 | H19: =G19*F19*E19 -> 53.568 | I19: =$I$16 -> Đơn giá (VNĐ) | J19: =I19*H19 -> #VALUE!
A20: 2 | B20: Tấm số 2 | D20: m2 | E20: 1.08 | F20: 3.15 | G20: 8 | H20: =G20*F20*E20 -> 27.216 | I20: =$I$16 -> Đơn giá (VNĐ) | J20: =I20*H20 -> #VALUE!
A21: 3 | B21: Hao phí đơn hàng dưới 100m2 | D21: m2 | H21: 6 | I21: =$I$16 -> Đơn giá (VNĐ) | J21: =I21*H21 -> #VALUE!
A22: III. | B22: PHỤ KIỆN VÁCH: Không gấp mép * Tôn nền Kamaz, dày 0,45±0,04mm, AZM50, màu theo vách
G23: =SUM(G24:G25) -> 21 | H23: =SUM(H24:H25) -> 84 | J23: =SUM(J24:J25) -> 4080000
A24: 1 | B24: Khổ 400mm | D24: m | E24: 0.4 | F24: 4 | G24: 15 | H24: =G24*F24 -> 60 | I24: 42000 | J24: =I24*H24 -> 2520000
A25: 2 | B25: Khổ 600mm | D25: m | E25: 0.6 | F25: 4 | G25: 6 | H25: =G25*F25 -> 24 | I25: 65000 | J25: =I25*H25 -> 1560000
A27: Khách hàng nhận hàng lúc: …….... giờ …….. phút, ngày ….. tháng ….. năm 2026
A28: Người lập phiếu Người nhận hàng Lái xe Thủ kho BGĐ Nhà máy
A29: (ký, ghi rõ họ tên) (ký, ghi rõ họ tên) (ký, ghi rõ họ tên) (ký, ghi rõ họ tên) (ký, ghi rõ họ tên)
I35: =2.3+2.13+2.1+2.2 -> 8.73
