Workbook
Name ___NSO2: {"'Sheet1'!$L$16"}
Name __a1: {"'Sheet1'!$L$16"}
Name __h1: {"'Sheet1'!$L$16"}
Name __hu1: {"'Sheet1'!$L$16"}
Name __hu2: {"'Sheet1'!$L$16"}
Name __hu5: {"'Sheet1'!$L$16"}
Name __hu6: {"'Sheet1'!$L$16"}
Name __IntlFixup: TRUE
Name __NSO2: {"'Sheet1'!$L$16"}
Name __PA3: {"'Sheet1'!$L$16"}
Name _a1: {"'Sheet1'!$L$16"}
Name _a2: {"'Sheet1'!$L$16"}
Name _CN1: {"'Sheet1'!$L$16"}
Name _cn3: {"'Sheet1'!$L$16"}
Name _d1500: {"'Sheet1'!$L$16"}
Name _GD3: {"'Sheet1'!$L$16"}
Name _Goi8: {"'Sheet1'!$L$16"}
Name _h1: {"'Sheet1'!$L$16"}
Name _hu1: {"'Sheet1'!$L$16"}
Name _hu2: {"'Sheet1'!$L$16"}
Name _hu5: {"'Sheet1'!$L$16"}
Name _hu6: {"'Sheet1'!$L$16"}
Name _NSO2: {"'Sheet1'!$L$16"}
Name _Order1: 255
Name _Order2: 255
Name _PA3: {"'Sheet1'!$L$16"}
Name _Regression_Int: 1
Name _T2: {"'Sheet1'!$L$16"}
Name aaafff: {"'장비'!$A$3:$M$12"}
Name AccessDatabase: "D:\_genkou\excel97\sample\支店集計作業\本社合計2.mdb"
Name ADITION: {"'장비'!$A$3:$M$12"}
Name agfg: {"'장비'!$A$3:$M$12"}
Name anscount: 1
Name AS2DocOpenMode: "AS2DocumentEdit"
Name ATGT: {"'Sheet1'!$L$16"}
Name bc: {"'Sheet1'!$L$16"}
Name BCTQ: {"'Sheet1'!$L$16"}
Name btl: {"'Sheet1'!$L$16"}
Name chitietbgiang2: {"'Sheet1'!$L$16"}
Name chuyen: {"'Sheet1'!$L$16"}
Name civil2: {"'장비'!$A$3:$M$12"}
Name cn2a: {"'Sheet1'!$L$16"}
Name CON: {"'Sheet1'!$L$16"}
Name concrete: {"'Sheet1'!$L$16"}
Name CTCT1: {"'Sheet1'!$L$16"}
Name dddf: {"'장비'!$A$3:$M$12"}
Name dfaf: {"'장비'!$A$3:$M$12"}
Name dfdf: {"'장비'!$A$3:$M$12"}
Name DIAMOND: {"'장비'!$A$3:$M$12"}
Name ert: {"'장비'!$A$3:$M$12"}
Name erty: {"'장비'!$A$3:$M$12"}
Name EWRWE: {"'장비'!$A$3:$M$12"}
Name ewrweq: {"'장비'!$A$3:$M$12"}
Name fffffffg: {"'장비'!$A$3:$M$12"}
Name ffgfg: {"'장비'!$A$3:$M$12"}
Name FIRST: {"'Sheet1'!$L$16"}
Name FORMWORK: {"'Sheet1'!$L$16"}
Name ga: {"'Sheet1'!$L$16"}
Name gggg: {"'장비'!$A$3:$M$12"}
Name gh: {"'Sheet1'!$L$16"}

Sheet 1.KH
B1: 1 | C1: 2 | D1: 3 | E1: 4 | F1: 5 | G1: 6 | H1: 7 | I1: 8 | J1: 9 | K1: 10 | L1: 11 | M1: 2 | N1: 13 | O1: 14 | P1: 15 | Q1: 16 | R1: 17 | S1: 18 | T1: 19 | U1: 20
A2: MÃ KHÁCH | B2: MKH | C2: NVT | D2: Tên doanh nghiệp/Khách hàng | E2: Lĩnh vực hoạt động chính | F2: MST | G2: Người đại diện | H2: Di động/Zalo | I2: Email | J2: Địa chỉ | N2: Telephone | O2: Fax | P2: Website | Q2: Nhân viên Phụ Trách | R2: Số TK | S2: Mở tại…
J3: Địa chỉ chi tiết | K3: Xã/ Phường | L3: Quận/ Huyện | M3: Tỉnh/TP
A4: Mr Phóng | B4: 100 | D4: Quý khách hàng. | G4: - | H4: -
A5: Mr Phóng | C5: 100.1
A6: Mr Phóng | B6: 101 | C6: 101.1 | D6: Phòng Kinh doanh Ngọc Hồi - Công ty Phú Sơn | G6: Mr Phóng | H6: 0866989399 | J6: Lô 7CN5 CCN Ngọc Hồi - X. Ngọc Hồi, H. Thanh Trì, TP. Hà Nội
A7: Mr Phóng | B7: 1 | D7: CÔNG TY TNHH SYPANEL VINA | E7: Thi công Nhà xưởng | F7: 0900863224-001 | G7: KWON JUNG HYUN | H7: (+84) 2213 946 170 | J7: KCN Minh Đức, xã Bạch Sam, huyện Mỹ Hào, tỉnh Hưng Yên | K7: Bạch Sam | L7: Mỹ Hào | M7: Hưng Yên | N7: 03213946170 | O7: 03213.946.171 | P7: http://www.sypanelvina.vn/ | Q7: Trần Văn Phóng | R7: 190088881500-01 | S7: Ngân hàng TMCP Quân đội - Chi nhánh Quận Tân Bình - TP Hồ Chí Minh
C8: 1.1 | G8: Mr Kwon
C9: 1.2 | G9: Mr Cường | H9: 0902804007
C10: 1.3 | G10: Mr Tuyên | H10: 0986452504
C11: 1.4 | G11: Mr Quyết | H11: 0934549768
C12: 1.5

Sheet 2.Báo giá
C1: CÔNG TY TNHH CÔNG NGHỆ CÔNG NGHIỆP PHÚ SƠN | J1: =$M$1&"."&$M$2 -> 1.2 | L1: Mã KH: | M1: 1 | W1: =$J$61 -> 2045070 | X1: =RIGHT("000000000000"&ROUND(W1,0),12) -> 000002045070 | Y1: 1 | Z1: 2 | AA1: 3 | AB1: 4 | AC1: 5 | AD1: 6 | AE1: 7 | AF1: 8 | AG1: 9 | AH1: 10 | AI1: 11 | AJ1: 12
C2: Địa chỉ: Lô 7 CN5, Cụm công nghiệp Ngọc Hồi, xã Ngọc Hồi, Thành phố Hà Nội | L2: Mã liên hệ: | M2: 2 | Y2: =VALUE(MID(X1,Y1,1)) -> 0 | Z2: =VALUE(MID(X1,Z1,1)) -> 0 | AA2: =VALUE(MID(X1,AA1,1)) -> 0 | AB2: =VALUE(MID(X1,AB1,1)) -> 0 | AC2: =VALUE(MID(X1,AC1,1)) -> 0 | AD2: =VALUE(MID(X1,AD1,1)) -> 2 | AE2: =VALUE(MID(X1,AE1,1)) -> 0 | AF2: =VALUE(MID(X1,AF1,1)) -> 4 | AG2: =VALUE(MID(X1,AG1,1)) -> 5 | AH2: =VALUE(MID(X1,AH1,1)) -> 0 | AI2: =VALUE(MID(X1,AI1,1)) -> 7 | AJ2: =VALUE(MID(X1,AJ1,1)) -> 0
C3: MST: 0104113174 | D3: https://panelphuson.vn | H3: https://javta.vn | L3: Ngày: | M3: =NOW() -> 46197.445 | Y3: =SUM(Y2) -> 0 | Z3: =SUM(Y2:Z2) -> 0 | AA3: =SUM(Y2:AA2) -> 0 | AB3: =SUM(AB2) -> 0 | AC3: =SUM(AB2:AC2) -> 0 | AD3: =SUM(AB2:AD2) -> 2 | AE3: =SUM(AE2) -> 0 | AF3: =SUM(AE2:AF2) -> 4 | AG3: =SUM(AE2:AG2) -> 9 | AH3: =SUM(AH2) -> 0 | AI3: =SUM(AH2:AI2) -> 7 | AJ3: =SUM(AH2:AJ2) -> 7
A4: BẢNG BÁO GIÁ SẢN PHẨM - KIÊM XÁC NHẬN ĐƠN HÀNG | L4: Số ngày BG | M4: 2 | Y4: =IF(Y2=0,"",CHOOSE(Y2,"một","hai","ba","bốn","năm","sáu","bảy","tám","chín")) | Z4: =IF(Z2=0,IF(AND(Y2<>0,AA2<>0),"lẻ",""),CHOOSE(Z2,"mười","hai","ba","bốn","năm","sáu","bảy","tám","chín")) | AA4: =IF(AA2=0,"",CHOOSE(AA2,IF(Z2>1,"mốt","một"),"hai","ba","bốn",IF(Z2=0,"năm","lăm"),"sáu","bảy","tám","chín")) | AB4: =IF(AB2=0,"",CHOOSE(AB2,"một","hai","ba","bốn","năm","sáu","bảy","tám","chín")) | AC4: =IF(AC2=0,IF(AND(AB2<>0,AD2<>0),"lẻ",""),CHOOSE(AC2,"mười","hai","ba","bốn","năm","sáu","bảy","tám","chín")) | AD4: =IF(AD2=0,"",CHOOSE(AD2,IF(AC2>1,"mốt","một"),"hai","ba","bốn",IF(AC2=0,"năm","lăm"),"sáu","bảy","tám","chín")) -> hai | AE4: =IF(AE2=0,"",CHOOSE(AE2,"một","hai","ba","bốn","năm","sáu","bảy","tám","chín")) | AF4: =IF(AF2=0,IF(AND(AE2<>0,AG2<>0),"lẻ",""),CHOOSE(AF2,"mười","hai","ba","bốn","năm","sáu","bảy","tám","chín")) -> bốn | AG4: =IF(AG2=0,"",CHOOSE(AG2,IF(AF2>1,"mốt","một"),"hai","ba","bốn",IF(AF2=0,"năm","lăm"),"sáu","bảy","tám","chín")) -> lăm | AH4: =IF(AH2=0,"",CHOOSE(AH2,"một","hai","ba","bốn","năm","sáu","bảy","tám","chín")) | AI4: =IF(AI2=0,IF(AND(AH2<>0,AJ2<>0),"lẻ",""),CHOOSE(AI2,"mười","hai","ba","bốn","năm","sáu","bảy","tám","chín")) -> bảy | AJ4: =IF(AJ2=0,"",CHOOSE(AJ2,IF(AI2>1,"mốt","một"),"hai","ba","bốn",IF(AI2=0,"năm","lăm"),"sáu","bảy","tám","chín"))
E5: ="Số:"&HOUR($M$3)&"."&DAY($M$3)&""&MONTH($M$3)&".BG/KDNH/2026" -> Số:10.246.BG/KDNH/2026 | L5: Hiệu lực đến: | M5: =M3+M4 -> 46199.445 | Y5: =IF(Y2=0,"","trăm") | Z5: =IF(Z2=0,"",IF(Z2=1,"","mươi")) | AA5: =IF(AND(AA2=0,AA3=0),"","tỷ,") | AB5: =IF(AB2=0,"","trăm") | AC5: =IF(AC2=0,"",IF(AC2=1,"","mươi")) | AD5: =IF(AND(AD2=0,AD3=0),"","triệu,") -> triệu, | AE5: =IF(AE2=0,"","trăm") | AF5: =IF(AF2=0,"",IF(AF2=1,"","mươi")) -> mươi | AG5: =IF(AND(AG2=0,AG3=0),"","ngàn,") -> ngàn, | AH5: =IF(AH2=0,"","trăm") | AI5: =IF(AI2=0,"",IF(AI2=1,"","mươi")) -> mươi
A6: Kính gửi: | C6: =VLOOKUP($M$1,'1.KH'!$B$2:$X$12,3,0) -> CÔNG TY TNHH SYPANEL VINA | H6: Người gửi: Trần Văn Phóng | X6: =UPPER(LEFT(TRIM(IF(W1=0,"không đồng.",Y4&" "&Y5&" "&Z4&" "&Z5&" "&AA4&" "&AA5&" "&AB4&" "&AB5&" "&AC4&" "&AC5&" "&AD4&" "&AD5&" "&AE4&" "&AE5&" "&AF4&" "&AF5&" "&AG4&" "&AG5&" "&AH4&" "&AH5&" "&AI4&" "&AI5&" "&AJ4&" "&AJ5)),1))&RIGHT(TRIM(IF(W1=0,"không đồng.",Y4&" "&Y5&" "&Z4&" "&Z5&" "&AA4&" "&AA5&" "&AB4&" "&AB5&" "&AC4&" "&AC5&" "&AD4&" "&AD5&" "&AE4&" "&AE5&" "&AF4&" "&AF5&" "&AG4&" "&AG5&" "&AH4&" "&AH5&" "&AI4&" "&AI5&" "&AJ4&" "&AJ5)),LEN(TRIM(IF(W1=0,"không đồng.",Y4&" "&Y5&" "&Z4&" "&Z5&" "&AA4&" "&AA5&" "&AB4&" "&AB5&" "&AC4&" "&AC5&" "&AD4&" "&AD5&" "&AE4&" "&AE5&" "&AF4&" "&AF5&" "&AG4&" "&AG5&" "&AH4&" "&AH5&" "&AI4&" "&AI5&" "&AJ4&" "&AJ5)))-1) -> Hai triệu, bốn mươi lăm ngàn, bảy mươi
A7: Địa chỉ: | C7: =VLOOKUP($M$1,'1.KH'!$B$2:$X$12,9,0) -> KCN Minh Đức, xã Bạch Sam, huyện Mỹ Hào, tỉnh Hưng Yên | H7: Điện thoại: 0982.48.63.36 | X7: =""&$X$6&" đồng ./." -> Hai triệu, bốn mươi lăm ngàn, bảy mươi đồng ./.
A8: Người liên hệ: | C8: =VLOOKUP($J$1,'1.KH'!$C$2:$X$12,5,0) -> Mr Cường | H8: =" Ngày báo giá: "&DAY($M$3)&"/"&MONTH($M$3)&"/"&YEAR($M$3) -> Ngày báo giá: 24/6/2026
A9: Điện thoại: | C9: =VLOOKUP($J$1,'1.KH'!$C$2:$X$12,6,0) -> 0902804007 | H9: =" Hiệu lực đến ngày: "&DAY($M$5)&"/"&MONTH($M$5)&"/"&YEAR($M$5) -> Hiệu lực đến ngày: 26/6/2026
A10: Cảm ơn Quý khách hàng đã quan tâm tới sản phẩm do Công ty TNHH Công nghệ Công nghiệp Phú Sơn sản xuất. Chúng tôi xin gửi Báo giá sản phẩm theo yêu cầu Quý khách đã cung cấp với nội dung như sau: | K10: - Báo giá khách thì để giá bao gồm VAT
A11: TT | B11: Tên sản phẩm/Quy cách | D11: Đơn vị | E11: Chiều rộng | F11: Chiều dài | G11: Số tấm | H11: Khối lượng | I11: Đơn giá (VNĐ) | J11: Thành tiền (VNĐ)
B12: PANEL PUR VÁCH TRONG (TÔN + PU + TÔN): * Mặt thứ nhất: Tôn nền Kamazn, dày 0,45±0,04mm, AZM50 màu KM W01. * Lớp giữa: PUR dày 50±2mm, tỷ trọng 40±3kg/m3. * Mặt thứ hai: Tôn nền Kamazn, dày 0,45±0,04mm, AZM50 màu KM W01. * Hai mặt tôn phẳng hoặc cán gân tăng cứng. Khổ hiệu dụng/khổ sản phẩm: 1.130/1.152 mm (hoặc 1.000/1.022mm). Có dán nilong chống trầy xước. Tính m2 = chiều dài(m) x số tấm x 1,13
G13: =SUM(G14:G14) -> 1 | H13: =SUM(H14:H14) -> 1.13 | I13: 409000 | J13: =I13*H13 -> 462170
A14: 1 | B14: Tấm số 01 | D14: m2 | E14: 1.13 | F14: 1 | G14: 1 | H14: =E14*F14*G14 -> 1.13
B15: PANEL PUR VÁCH NGOÀI (TÔN + PU + TÔN): * Mặt ngoài: Tôn nền Kamazn, dày 0,45±0,04mm, AZM50, màu KM W01. * Lớp giữa: PUR 50±2mm, tỷ trọng 40±3kg/m3 * Mặt trong: Tôn nền Kamazn, dày 0,40±0,04mm, AZM50, màu KM W01. * Mặt ngoài có 1 gân to âm & 32 gân nhỏ sóng tăm. Mặt trong phẳng hoặc có gân. Dán nilong chống trầy xước. Khổ hiệu dụng/khổ sản phẩm: 1.000/1.022mm. Tính m2 = chiều dài(m) x số tấm x 1,00
G16: =SUM(G17:G17) -> 1 | H16: =SUM(H17:H17) -> 1 | I16: 415000 | J16: =I16*H16 -> 415000
A17: 1 | B17: Tấm số 01 | D17: m2 | E17: 1 | F17: 1 | G17: 1 | H17: =E17*F17*G17 -> 1
B18: PANEL EPS VÁCH TRONG (TÔN + EPS + TÔN): * Mặt thứ nhất: Tôn nền Kamazn, dày 0,45±0,04mm, AZM50, màu KM W01 * Lớp giữa: EPS trắng thường dày 50±2mm, tỷ trọng 8±1kg/m3 * Mặt thứ hai: Tôn nền Kamazn, dày 0,45±0,04mm, AZM50, màu KM W01 * Hai mặt phẳng hoặc có gân tăng cứng. Khổ hiệu dụng/khổ sản phẩm: 1000/1025mm hoặc ngàm U tôn 1150/1170mm, có dán nilong chống trầy xước. Tính m2 = chiều dài(m) x số tấm x 1,00 (Ngàm U x 1,15)
G19: =SUM(G20:G20) -> 1 | H19: =SUM(H20:H20) -> 1 | I19: 232000 | J19: =I19*H19 -> 232000
A20: 1 | B20: Tấm số 01 | D20: m2 | E20: 1 | F20: 1 | G20: 1 | H20: =E20*F20*G20 -> 1
B21: PANEL EPS VÁCH NGOÀI (TÔN + EPS + TÔN): * Mặt ngoài: Tôn nền Kamazn dày 0,45±0,04mm, AZM50 màu KM W01 * Lớp giữa: EPS trắng thường dày 50±2mm & tỷ trọng 8±1kg/m3 * Mặt trong: Tôn nền Kamazn dày 0,45±0,04mm, AZM50 màu KM W01 * Mặt ngoài có 1 gân to âm & 32 gân nhỏ sóng tăm. Mặt trong phẳng hoặc có gân tăng cứng. Khổ hiệu dụng/khổ sản phẩm: 1.000/1.045mm, có dán nilong chống trầy xước. Tính m2 = chiều dài(m) x số tấm x 1,00
G22: =SUM(G23:G23) -> 1 | H22: =SUM(H23:H23) -> 1 | I22: 243000 | J22: =I22*H22 -> 243000
A23: 1 | B23: Tấm số 01 | D23: m2 | E23: 1 | F23: 1 | G23: 1 | H23: =E23*F23*G23 -> 1
B24: KLIPLOCK PU 2 SÓNG (TÔN + PU + TÔN/GIẤY BẠC): * Mặt trên: Tôn nền Kamazn, dày 0,45±0,04mm, AZM50, màu KM W02 * Lớp giữa: PU chống cháy lan B2, dày 20±2mm, tỷ trọng 32±3kg/m3 * Mặt dưới: Tôn nền liên doanh, dày 0,23±0,04mm, có hèm chống hở, màu trắng hoặc giấy bạc sần * Chiều cao sóng dương 42±1mm, Khổ hiệu dụng/khổ sản phẩm: 400/450mm hoặc 450/485mm * Tính m2 = chiều dài(m) x số tấm x 0,45 hoặc 0,485
G25: =SUM(G26:G26) -> 1 | H25: =SUM(H26:H26) -> 0.45 | I25: 230000 | J25: =I25*H25 -> 103500
A26: 1 | B26: Tấm số 01 | D26: m2 | E26: 0.45 | F26: 1 | G26: 1 | H26: =E26*F26*G26 -> 0.45
A27: VI. | B27: TẤM LỢP PU 5 SÓNG (TÔN + PU + TÔN hoặc GIẤY BẠC): * Mặt trên: Tôn nền Kamazn, dày 0,45±0,04mm, AZM50, màu KM W02 * Lớp giữa: PU chống cháy lan B2, dày 20±2mm, tỷ trọng 29±3kg/m3 * Mặt dưới: Tôn nền liên doanh dày 0,23±0,04mm, có hèm chống hở, màu trắng hoặc Giấy bạc hoa. * Chiều cao sóng dương 32±2mm. Khổ hiệu dụng/khổ sản phẩm: 1.000/1.080mm. Tính m2 = chiều dài(m) x số tấm x 1,08
G28: =SUM(G29:G29) -> 1 | H28: =SUM(H29:H29) -> 1.08 | I28: 215000 | J28: =I28*H28 -> 232200
A29: 1 | B29: Tấm số 01 | D29: m2 | E29: 1.08 | F29: 1 | G29: 1 | H29: =E29*F29*G29 -> 1.08
B30: TẤM LỢP EPS 5 SÓNG (TÔN + EPS + TÔN): * Mặt trên: Tôn nền Kamazn, dày 0,45±0,04mm, AZM50, màu KM W02 * Lớp giữa: EPS trắng thường, dày 50±2mm, tỷ trọng 8±1kg/m3 * Mặt dưới: Tôn nền liên doanh dày 0,23±0,04mm, màu trắng. * Chiều cao sóng dương 35±2mm. Khổ hiệu dụng/khổ sản phẩm: 1.000/1.105mm. Tính m2 = chiều dài(m) x số tấm x 1,00
G31: =SUM(G32:G32) -> 1 | H31: =SUM(H32:H32) -> 1.08 | I31: 215000 | J31: =I31*H31 -> 232200
A32: 1 | B32: Tấm số 01 | D32: m2 | E32: 1.08 | F32: 1 | G32: 1 | H32: =E32*F32*G32 -> 1.08
B33: TẤM LỢP SEAMLOCK K1000: * Tôn nền Kamazn, dày 0,45±0,04mm, AZM50, màu KM W02. * Hiệu dụng 1.000mm, chiều cao sóng dương 81±1mm.
G34: =SUM(G35:G35) -> 1 | H34: =SUM(H35:H35) -> 1 | I34: 125000 | J34: =I34*H34 -> 125000
A35: 1 | B35: Tấm số 01 | D35: m2 | E35: 1 | F35: 1 | G35: 1 | H35: =E35*F35*G35 -> 1
B36: VẬT TƯ PHỤ:
A37: 1 | B37: Đai seamlock liền | D37: bộ | G37: 1 | H37: 1 | I37: 19000
A38: 2 | B38: Đai seamlock đơn | D38: cái | G38: 1 | H38: 1 | I38: 7000
A39: 3 | B39: Bộ chặn trên dưới seamlock | D39: bộ | G39: 1 | H39: 1 | I39: 13000
B40: PHỤ KIỆN: * Tôn nền Kamazn, dày 0,45±0,04mm, AZM50, màu KM W02.
...

Sheet 4.LSX-Nội bộ
C1: CÔNG TY TNHH CÔNG NGHỆ CÔNG NGHIỆP PHÚ SƠN | J1: =$L$1&"."&$L$2 -> 1.2 | K1: Mã KH: | L1: ='2.Báo giá'!$M$1 -> 1 | V1: =$J$59 -> 989399 | W1: =RIGHT("000000000000"&ROUND(V1,0),12) -> 000000989399 | X1: 1 | Y1: 2 | Z1: 3 | AA1: 4 | AB1: 5 | AC1: 6 | AD1: 7 | AE1: 8 | AF1: 9 | AG1: 10 | AH1: 11 | AI1: 12
C2: Địa chỉ: Lô 7 CN5, Cụm công nghiệp Ngọc Hồi, xã Ngọc Hồi, Thành phố Hà Nội | K2: Mã liên hệ: | L2: ='2.Báo giá'!$M$2 -> 2 | X2: =VALUE(MID(W1,X1,1)) -> 0 | Y2: =VALUE(MID(W1,Y1,1)) -> 0 | Z2: =VALUE(MID(W1,Z1,1)) -> 0 | AA2: =VALUE(MID(W1,AA1,1)) -> 0 | AB2: =VALUE(MID(W1,AB1,1)) -> 0 | AC2: =VALUE(MID(W1,AC1,1)) -> 0 | AD2: =VALUE(MID(W1,AD1,1)) -> 9 | AE2: =VALUE(MID(W1,AE1,1)) -> 8 | AF2: =VALUE(MID(W1,AF1,1)) -> 9 | AG2: =VALUE(MID(W1,AG1,1)) -> 3 | AH2: =VALUE(MID(W1,AH1,1)) -> 9 | AI2: =VALUE(MID(W1,AI1,1)) -> 9
C3: MST: 0104113174 | E3: https://panelphuson.vn | H3: https://javta.vn | K3: Ngày: | L3: =NOW() -> 46197.445 | X3: =SUM(X2) -> 0 | Y3: =SUM(X2:Y2) -> 0 | Z3: =SUM(X2:Z2) -> 0 | AA3: =SUM(AA2) -> 0 | AB3: =SUM(AA2:AB2) -> 0 | AC3: =SUM(AA2:AC2) -> 0 | AD3: =SUM(AD2) -> 9 | AE3: =SUM(AD2:AE2) -> 17 | AF3: =SUM(AD2:AF2) -> 26 | AG3: =SUM(AG2) -> 3 | AH3: =SUM(AG2:AH2) -> 12 | AI3: =SUM(AG2:AI2) -> 21
C4: Số lệnh sản xuất: | D4: 6580 | E4: /PS | H4: Thời gian gửi: | I4: =NOW() -> 46197.445 | M4: 2 | X4: =IF(X2=0,"",CHOOSE(X2,"một","hai","ba","bốn","năm","sáu","bảy","tám","chín")) | Y4: =IF(Y2=0,IF(AND(X2<>0,Z2<>0),"lẻ",""),CHOOSE(Y2,"mười","hai","ba","bốn","năm","sáu","bảy","tám","chín")) | Z4: =IF(Z2=0,"",CHOOSE(Z2,IF(Y2>1,"mốt","một"),"hai","ba","bốn",IF(Y2=0,"năm","lăm"),"sáu","bảy","tám","chín")) | AA4: =IF(AA2=0,"",CHOOSE(AA2,"một","hai","ba","bốn","năm","sáu","bảy","tám","chín")) | AB4: =IF(AB2=0,IF(AND(AA2<>0,AC2<>0),"lẻ",""),CHOOSE(AB2,"mười","hai","ba","bốn","năm","sáu","bảy","tám","chín")) | AC4: =IF(AC2=0,"",CHOOSE(AC2,IF(AB2>1,"mốt","một"),"hai","ba","bốn",IF(AB2=0,"năm","lăm"),"sáu","bảy","tám","chín")) | AD4: =IF(AD2=0,"",CHOOSE(AD2,"một","hai","ba","bốn","năm","sáu","bảy","tám","chín")) -> chín | AE4: =IF(AE2=0,IF(AND(AD2<>0,AF2<>0),"lẻ",""),CHOOSE(AE2,"mười","hai","ba","bốn","năm","sáu","bảy","tám","chín")) -> tám | AF4: =IF(AF2=0,"",CHOOSE(AF2,IF(AE2>1,"mốt","một"),"hai","ba","bốn",IF(AE2=0,"năm","lăm"),"sáu","bảy","tám","chín")) -> chín | AG4: =IF(AG2=0,"",CHOOSE(AG2,"một","hai","ba","bốn","năm","sáu","bảy","tám","chín")) -> ba | AH4: =IF(AH2=0,IF(AND(AG2<>0,AI2<>0),"lẻ",""),CHOOSE(AH2,"mười","hai","ba","bốn","năm","sáu","bảy","tám","chín")) -> chín | AI4: =IF(AI2=0,"",CHOOSE(AI2,IF(AH2>1,"mốt","một"),"hai","ba","bốn",IF(AH2=0,"năm","lăm"),"sáu","bảy","tám","chín")) -> chín
C5: LỆNH SẢN XUẤT | X5: =IF(X2=0,"","trăm") | Y5: =IF(Y2=0,"",IF(Y2=1,"","mươi")) | Z5: =IF(AND(Z2=0,Z3=0),"","tỷ,") | AA5: =IF(AA2=0,"","trăm") | AB5: =IF(AB2=0,"",IF(AB2=1,"","mươi")) | AC5: =IF(AND(AC2=0,AC3=0),"","triệu,") | AD5: =IF(AD2=0,"","trăm") -> trăm | AE5: =IF(AE2=0,"",IF(AE2=1,"","mươi")) -> mươi | AF5: =IF(AND(AF2=0,AF3=0),"","ngàn,") -> ngàn, | AG5: =IF(AG2=0,"","trăm") -> trăm | AH5: =IF(AH2=0,"",IF(AH2=1,"","mươi")) -> mươi
A6: Khách hàng: | C6: =VLOOKUP($L$1,'1.KH'!$B$2:$X$12,3,0) -> CÔNG TY TNHH SYPANEL VINA | I6: NVKD: Trần Văn Phóng | W6: =UPPER(LEFT(TRIM(IF(V1=0,"không đồng.",X4&" "&X5&" "&Y4&" "&Y5&" "&Z4&" "&Z5&" "&AA4&" "&AA5&" "&AB4&" "&AB5&" "&AC4&" "&AC5&" "&AD4&" "&AD5&" "&AE4&" "&AE5&" "&AF4&" "&AF5&" "&AG4&" "&AG5&" "&AH4&" "&AH5&" "&AI4&" "&AI5)),1))&RIGHT(TRIM(IF(V1=0,"không đồng.",X4&" "&X5&" "&Y4&" "&Y5&" "&Z4&" "&Z5&" "&AA4&" "&AA5&" "&AB4&" "&AB5&" "&AC4&" "&AC5&" "&AD4&" "&AD5&" "&AE4&" "&AE5&" "&AF4&" "&AF5&" "&AG4&" "&AG5&" "&AH4&" "&AH5&" "&AI4&" "&AI5)),LEN(TRIM(IF(V1=0,"không đồng.",X4&" "&X5&" "&Y4&" "&Y5&" "&Z4&" "&Z5&" "&AA4&" "&AA5&" "&AB4&" "&AB5&" "&AC4&" "&AC5&" "&AD4&" "&AD5&" "&AE4&" "&AE5&" "&AF4&" "&AF5&" "&AG4&" "&AG5&" "&AH4&" "&AH5&" "&AI4&" "&AI5)))-1) -> Chín trăm tám mươi chín ngàn, ba trăm chín mươi chín
A7: Liên hệ: | C7: =VLOOKUP($J$1,'1.KH'!$C$2:$X$12,5,0) -> Mr Cường | D7: Điện thoại: | F7: =VLOOKUP($J$1,'1.KH'!$C$2:$X$12,6,0) -> 0902804007 | I7: Điện thoại: 0982.48.63.36 | W7: =""&$W$6&" đồng ./." -> Chín trăm tám mươi chín ngàn, ba trăm chín mươi chín đồng ./.
A8: * NỘI DUNG YÊU CẦU SẢN XUẤT:
A9: TT | B9: Tên sản phẩm/Quy cách | D9: Đơn vị | E9: Chiều rộng | F9: Chiều dài | G9: Số tấm | H9: Khối lượng | I9: Đơn giá (VNĐ) | J9: Thành tiền (VNĐ) | K9: - Nội bộ để giá trước VAT; Tổng VAT8 hoặc 10 thành nhóm riên
B10: PANEL PUR VÁCH TRONG (TÔN + PU + TÔN): * Mặt thứ nhất: Tôn nền Kamazn, dày 0,45±0,04mm, AZM50 màu KM W01. * Lớp giữa: PUR dày 50±2mm, tỷ trọng 40±3kg/m3. * Mặt thứ hai: Tôn nền Kamazn, dày 0,45±0,04mm, AZM50 màu KM W01. * Hai mặt tôn phẳng hoặc cán gân tăng cứng. Khổ hiệu dụng/khổ sản phẩm: 1.130/1.152 mm (hoặc 1.000/1.022mm). Có dán nilong chống trầy xước. Tính m2 = chiều dài(m) x số tấm x 1,13
G11: =SUM(G12:G12) -> 1 | H11: =SUM(H12:H12) -> 1.13 | I11: 409000 | J11: =I11*H11 -> 462170
A12: 1 | B12: Tấm số 01 | D12: m2 | E12: 1.13 | F12: 1 | G12: 1 | H12: =E12*F12*G12 -> 1.13
B13: PANEL PUR VÁCH NGOÀI (TÔN + PU + TÔN): * Mặt ngoài: Tôn nền Kamazn, dày 0,45±0,04mm, AZM50, màu KM W01. * Lớp giữa: PUR 50±2mm, tỷ trọng 40±3kg/m3 * Mặt trong: Tôn nền Kamazn, dày 0,40±0,04mm, AZM50, màu KM W01. * Mặt ngoài có 1 gân to âm & 32 gân nhỏ sóng tăm. Mặt trong phẳng hoặc có gân. Dán nilong chống trầy xước. Khổ hiệu dụng/khổ sản phẩm: 1.000/1.022mm. Tính m2 = chiều dài(m) x số tấm x 1,00
G14: =SUM(G15:G15) -> 1 | H14: =SUM(H15:H15) -> 1 | I14: 415000 | J14: =I14*H14 -> 415000
A15: 1 | B15: Tấm số 01 | D15: m2 | E15: 1 | F15: 1 | G15: 1 | H15: =E15*F15*G15 -> 1
B16: PANEL EPS VÁCH TRONG (TÔN + EPS + TÔN): * Mặt thứ nhất: Tôn nền Kamazn, dày 0,45±0,04mm, AZM50, màu KM W01 * Lớp giữa: EPS trắng thường dày 50±2mm, tỷ trọng 8±1kg/m3 * Mặt thứ hai: Tôn nền Kamazn, dày 0,45±0,04mm, AZM50, màu KM W01 * Hai mặt phẳng hoặc có gân tăng cứng. Khổ hiệu dụng/khổ sản phẩm: 1000/1025mm hoặc ngàm U tôn 1150/1170mm, có dán nilong chống trầy xước. Tính m2 = chiều dài(m) x số tấm x 1,00 (Ngàm U x 1,15)
G17: =SUM(G18:G18) -> 1 | H17: =SUM(H18:H18) -> 1 | I17: 232000 | J17: =I17*H17 -> 232000
A18: 1 | B18: Tấm số 01 | D18: m2 | E18: 1 | F18: 1 | G18: 1 | H18: =E18*F18*G18 -> 1
B19: PANEL EPS VÁCH NGOÀI (TÔN + EPS + TÔN): * Mặt ngoài: Tôn nền Kamazn dày 0,45±0,04mm, AZM50 màu KM W01 * Lớp giữa: EPS trắng thường dày 50±2mm & tỷ trọng 8±1kg/m3 * Mặt trong: Tôn nền Kamazn dày 0,45±0,04mm, AZM50 màu KM W01 * Mặt ngoài có 1 gân to âm & 32 gân nhỏ sóng tăm. Mặt trong phẳng hoặc có gân tăng cứng. Khổ hiệu dụng/khổ sản phẩm: 1.000/1.045mm, có dán nilong chống trầy xước. Tính m2 = chiều dài(m) x số tấm x 1,00
G20: =SUM(G21:G21) -> 1 | H20: =SUM(H21:H21) -> 1 | I20: 243000 | J20: =I20*H20 -> 243000
A21: 1 | B21: Tấm số 01 | D21: m2 | E21: 1 | F21: 1 | G21: 1 | H21: =E21*F21*G21 -> 1 | I21: =2.3+2.13+2.1+2.2 -> 8.73
B22: KLIPLOCK PU 2 SÓNG (TÔN + PU + TÔN/GIẤY BẠC): * Mặt trên: Tôn nền Kamazn, dày 0,45±0,04mm, AZM50, màu KM W02 * Lớp giữa: PU chống cháy lan B2, dày 20±2mm, tỷ trọng 32±3kg/m3 * Mặt dưới: Tôn nền liên doanh, dày 0,23±0,04mm, có hèm chống hở, màu trắng hoặc giấy bạc sần * Chiều cao sóng dương 42±1mm, Khổ hiệu dụng/khổ sản phẩm: 400/450mm hoặc 450/485mm * Tính m2 = chiều dài(m) x số tấm x 0,45 hoặc 0,485
G23: =SUM(G24:G24) -> 1 | H23: =SUM(H24:H24) -> 0.45 | I23: 230000 | J23: =I23*H23 -> 103500
A24: 1 | B24: Tấm số 01 | D24: m2 | E24: 0.45 | F24: 1 | G24: 1 | H24: =E24*F24*G24 -> 0.45
A25: VI. | B25: TẤM LỢP PU 5 SÓNG (TÔN + PU + TÔN hoặc GIẤY BẠC): * Mặt trên: Tôn nền Kamazn, dày 0,45±0,04mm, AZM50, màu KM W02 * Lớp giữa: PU chống cháy lan B2, dày 20±2mm, tỷ trọng 29±3kg/m3 * Mặt dưới: Tôn nền liên doanh dày 0,23±0,04mm, có hèm chống hở, màu trắng hoặc Giấy bạc hoa. * Chiều cao sóng dương 32±2mm. Khổ hiệu dụng/khổ sản phẩm: 1.000/1.080mm. Tính m2 = chiều dài(m) x số tấm x 1,08
G26: =SUM(G27:G27) -> 1 | H26: =SUM(H27:H27) -> 1.08 | I26: 215000 | J26: =I26*H26 -> 232200
A27: 1 | B27: Tấm số 01 | D27: m2 | E27: 1.08 | F27: 1 | G27: 1 | H27: =E27*F27*G27 -> 1.08
B28: TẤM LỢP EPS 5 SÓNG (TÔN + EPS + TÔN): * Mặt trên: Tôn nền Kamazn, dày 0,45±0,04mm, AZM50, màu KM W02 * Lớp giữa: EPS trắng thường, dày 50±2mm, tỷ trọng 8±1kg/m3 * Mặt dưới: Tôn nền liên doanh dày 0,23±0,04mm, màu trắng. * Chiều cao sóng dương 35±2mm. Khổ hiệu dụng/khổ sản phẩm: 1.000/1.105mm. Tính m2 = chiều dài(m) x số tấm x 1,00
G29: =SUM(G30:G30) -> 1 | H29: =SUM(H30:H30) -> 1.08 | I29: 215000 | J29: =I29*H29 -> 232200
A30: 1 | B30: Tấm số 01 | D30: m2 | E30: 1.08 | F30: 1 | G30: 1 | H30: =E30*F30*G30 -> 1.08
B31: TẤM LỢP SEAMLOCK K1000: * Tôn nền Kamazn, dày 0,45±0,04mm, AZM50, màu KM W02. * Hiệu dụng 1.000mm, chiều cao sóng dương 81±1mm.
G32: =SUM(G33:G33) -> 1 | H32: =SUM(H33:H33) -> 1 | I32: 125000 | J32: =I32*H32 -> 125000
A33: 1 | B33: Tấm số 01 | D33: m2 | E33: 1 | F33: 1 | G33: 1 | H33: =E33*F33*G33 -> 1
B34: VẬT TƯ PHỤ:
A35: 1 | B35: Đai seamlock liền | D35: bộ | G35: 1 | H35: 1 | I35: 19000
A36: 2 | B36: Đai seamlock đơn | D36: cái | G36: 1 | H36: 1 | I36: 7000
A37: 3 | B37: Bộ chặn trên dưới seamlock | D37: bộ | G37: 1 | H37: 1 | I37: 13000
B38: PHỤ KIỆN: * Tôn nền Kamazn, dày 0,45±0,04mm, AZM50, màu KM W02.
G39: =SUM(G40:G48) -> 9 | H39: =SUM(H40:H48) -> 9.2
A40: 1 | B40: Khổ 100mm | D40: m | E40: 0.1 | F40: 1.2 | G40: 1 | H40: =F40*G40 -> 1.2 | I40: =ROUND(($K$41/(1.2/E40)+$K$42)/1.1,-2) -> 0 | J40: =I40*H40 -> 0
...

Sheet 4.LSX-PXK
C1: CÔNG TY TNHH CÔNG NGHỆ CÔNG NGHIỆP PHÚ SƠN | J1: =$M$1&"."&$M$2 -> 1.2 | L1: Mã KH: | M1: ='2.Báo giá'!$M$1 -> 1 | W1: =#REF! -> #REF! | X1: =RIGHT("000000000000"&ROUND(W1,0),12) -> #REF! | Y1: 1 | Z1: 2 | AA1: 3 | AB1: 4 | AC1: 5 | AD1: 6 | AE1: 7 | AF1: 8 | AG1: 9 | AH1: 10 | AI1: 11 | AJ1: 12
C2: Địa chỉ: Lô 7 CN5, Cụm công nghiệp Ngọc Hồi, xã Ngọc Hồi, Thành phố Hà Nội | L2: Mã liên hệ: | M2: ='2.Báo giá'!$M$2 -> 2 | Y2: =VALUE(MID(X1,Y1,1)) -> #REF! | Z2: =VALUE(MID(X1,Z1,1)) -> #REF! | AA2: =VALUE(MID(X1,AA1,1)) -> #REF! | AB2: =VALUE(MID(X1,AB1,1)) -> #REF! | AC2: =VALUE(MID(X1,AC1,1)) -> #REF! | AD2: =VALUE(MID(X1,AD1,1)) -> #REF! | AE2: =VALUE(MID(X1,AE1,1)) -> #REF! | AF2: =VALUE(MID(X1,AF1,1)) -> #REF! | AG2: =VALUE(MID(X1,AG1,1)) -> #REF! | AH2: =VALUE(MID(X1,AH1,1)) -> #REF! | AI2: =VALUE(MID(X1,AI1,1)) -> #REF! | AJ2: =VALUE(MID(X1,AJ1,1)) -> #REF!
C3: MST: 0104113174 https://panelphuson.vn https://javta.vn | L3: Ngày: | M3: =NOW() -> 46197.445 | Y3: =SUM(Y2) -> #REF! | Z3: =SUM(Y2:Z2) -> #REF! | AA3: =SUM(Y2:AA2) -> #REF! | AB3: =SUM(AB2) -> #REF! | AC3: =SUM(AB2:AC2) -> #REF! | AD3: =SUM(AB2:AD2) -> #REF! | AE3: =SUM(AE2) -> #REF! | AF3: =SUM(AE2:AF2) -> #REF! | AG3: =SUM(AE2:AG2) -> #REF! | AH3: =SUM(AH2) -> #REF! | AI3: =SUM(AH2:AI2) -> #REF! | AJ3: =SUM(AH2:AJ2) -> #REF!
A4: LỆNH SẢN XUẤT KIÊM PHIẾU XUẤT KHO | M4: 2 | Y4: =IF(Y2=0,"","trăm") -> #REF! | Z4: =IF(Z2=0,"",IF(Z2=1,"","mươi")) -> #REF! | AA4: =IF(AND(AA2=0,AA3=0),"","tỷ,") -> #REF! | AB4: =IF(AB2=0,"","trăm") -> #REF! | AC4: =IF(AC2=0,"",IF(AC2=1,"","mươi")) -> #REF! | AD4: =IF(AND(AD2=0,AD3=0),"","triệu,") -> #REF! | AE4: =IF(AE2=0,"","trăm") -> #REF! | AF4: =IF(AF2=0,"",IF(AF2=1,"","mươi")) -> #REF! | AG4: =IF(AND(AG2=0,AG3=0),"","ngàn,") -> #REF! | AH4: =IF(AH2=0,"","trăm") -> #REF! | AI4: =IF(AI2=0,"",IF(AI2=1,"","mươi")) -> #REF!
C5: =" Ngày "&DAY(TODAY())&" tháng "& MONTH(TODAY())&" năm " &YEAR(TODAY()) -> Ngày 24 tháng 6 năm 2026 | G5: Số: | H5: ='4.LSX-Nội bộ'!$D$4&"/PS" -> 6580/PS
A6: Khách hàng: | C6: =VLOOKUP($M$1,'1.KH'!$B$2:$X$12,3,0) -> CÔNG TY TNHH SYPANEL VINA | X6: =UPPER(LEFT(TRIM(IF(W1=0,"không đồng.",#REF!&" "&Y4&" "&#REF!&" "&Z4&" "&#REF!&" "&AA4&" "&#REF!&" "&AB4&" "&#REF!&" "&AC4&" "&#REF!&" "&AD4&" "&#REF!&" "&AE4&" "&#REF!&" "&AF4&" "&#REF!&" "&AG4&" "&#REF!&" "&AH4&" "&#REF!&" "&AI4&" "&#REF!&" "&AJ4)),1))&RIGHT(TRIM(IF(W1=0,"không đồng.",#REF!&" "&Y4&" "&#REF!&" "&Z4&" "&#REF!&" "&AA4&" "&#REF!&" "&AB4&" "&#REF!&" "&AC4&" "&#REF!&" "&AD4&" "&#REF!&" "&AE4&" "&#REF!&" "&AF4&" "&#REF!&" "&AG4&" "&#REF!&" "&AH4&" "&#REF!&" "&AI4&" "&#REF!&" "&AJ4)),LEN(TRIM(IF(W1=0,"không đồng.",#REF!&" "&Y4&" "&#REF!&" "&Z4&" "&#REF!&" "&AA4&" "&#REF!&" "&AB4&" "&#REF!&" "&AC4&" "&#REF!&" "&AD4&" "&#REF!&" "&AE4&" "&#REF!&" "&AF4&" "&#REF!&" "&AG4&" "&#REF!&" "&AH4&" "&#REF!&" "&AI4&" "&#REF!&" "&AJ4)))-1) -> #REF!
A7: Địa chỉ: | C7: =VLOOKUP($M$1,'1.KH'!$B$2:$X$12,9,0) -> KCN Minh Đức, xã Bạch Sam, huyện Mỹ Hào, tỉnh Hưng Yên | X7: =UPPER(LEFT(TRIM(IF(W2=0,"không đồng.",#REF!&" "&Y6&" "&#REF!&" "&Z6&" "&#REF!&" "&AA6&" "&#REF!&" "&AB6&" "&#REF!&" "&AC6&" "&#REF!&" "&AD6&" "&#REF!&" "&AE6&" "&#REF!&" "&AF6&" "&#REF!&" "&AG6&" "&#REF!&" "&AH6&" "&#REF!&" "&AI6&" "&#REF!&" "&AJ6)),1))&RIGHT(TRIM(IF(W2=0,"không đồng.",#REF!&" "&Y6&" "&#REF!&" "&Z6&" "&#REF!&" "&AA6&" "&#REF!&" "&AB6&" "&#REF!&" "&AC6&" "&#REF!&" "&AD6&" "&#REF!&" "&AE6&" "&#REF!&" "&AF6&" "&#REF!&" "&AG6&" "&#REF!&" "&AH6&" "&#REF!&" "&AI6&" "&#REF!&" "&AJ6)),LEN(TRIM(IF(W2=0,"không đồng.",#REF!&" "&Y6&" "&#REF!&" "&Z6&" "&#REF!&" "&AA6&" "&#REF!&" "&AB6&" "&#REF!&" "&AC6&" "&#REF!&" "&AD6&" "&#REF!&" "&AE6&" "&#REF!&" "&AF6&" "&#REF!&" "&AG6&" "&#REF!&" "&AH6&" "&#REF!&" "&AI6&" "&#REF!&" "&AJ6)))-1) -> Không đồng.
A8: Thời gian giao: | C8: ='4.LSX-Nội bộ'!$H$67 -> Ngày …. | D8: Người nhận hàng: | G8: =VLOOKUP($M$1,'1.KH'!$B$2:$X$12,7,0) -> (+84) 2213 946 170 | X8: =UPPER(LEFT(TRIM(IF(W3=0,"không đồng.",#REF!&" "&Y7&" "&#REF!&" "&Z7&" "&#REF!&" "&AA7&" "&#REF!&" "&AB7&" "&#REF!&" "&AC7&" "&#REF!&" "&AD7&" "&#REF!&" "&AE7&" "&#REF!&" "&AF7&" "&#REF!&" "&AG7&" "&#REF!&" "&AH7&" "&#REF!&" "&AI7&" "&#REF!&" "&AJ7)),1))&RIGHT(TRIM(IF(W3=0,"không đồng.",#REF!&" "&Y7&" "&#REF!&" "&Z7&" "&#REF!&" "&AA7&" "&#REF!&" "&AB7&" "&#REF!&" "&AC7&" "&#REF!&" "&AD7&" "&#REF!&" "&AE7&" "&#REF!&" "&AF7&" "&#REF!&" "&AG7&" "&#REF!&" "&AH7&" "&#REF!&" "&AI7&" "&#REF!&" "&AJ7)),LEN(TRIM(IF(W3=0,"không đồng.",#REF!&" "&Y7&" "&#REF!&" "&Z7&" "&#REF!&" "&AA7&" "&#REF!&" "&AB7&" "&#REF!&" "&AC7&" "&#REF!&" "&AD7&" "&#REF!&" "&AE7&" "&#REF!&" "&AF7&" "&#REF!&" "&AG7&" "&#REF!&" "&AH7&" "&#REF!&" "&AI7&" "&#REF!&" "&AJ7)))-1) -> Không đồng.
A9: Giao hàng tại: | C9: ='4.LSX-Nội bộ'!$C$69 -> tại Nhà máy Phú Sơn | X9: =UPPER(LEFT(TRIM(IF(W4=0,"không đồng.",#REF!&" "&Y8&" "&#REF!&" "&Z8&" "&#REF!&" "&AA8&" "&#REF!&" "&AB8&" "&#REF!&" "&AC8&" "&#REF!&" "&AD8&" "&#REF!&" "&AE8&" "&#REF!&" "&AF8&" "&#REF!&" "&AG8&" "&#REF!&" "&AH8&" "&#REF!&" "&AI8&" "&#REF!&" "&AJ8)),1))&RIGHT(TRIM(IF(W4=0,"không đồng.",#REF!&" "&Y8&" "&#REF!&" "&Z8&" "&#REF!&" "&AA8&" "&#REF!&" "&AB8&" "&#REF!&" "&AC8&" "&#REF!&" "&AD8&" "&#REF!&" "&AE8&" "&#REF!&" "&AF8&" "&#REF!&" "&AG8&" "&#REF!&" "&AH8&" "&#REF!&" "&AI8&" "&#REF!&" "&AJ8)),LEN(TRIM(IF(W4=0,"không đồng.",#REF!&" "&Y8&" "&#REF!&" "&Z8&" "&#REF!&" "&AA8&" "&#REF!&" "&AB8&" "&#REF!&" "&AC8&" "&#REF!&" "&AD8&" "&#REF!&" "&AE8&" "&#REF!&" "&AF8&" "&#REF!&" "&AG8&" "&#REF!&" "&AH8&" "&#REF!&" "&AI8&" "&#REF!&" "&AJ8)))-1) -> Không đồng.
A10: Nhân viên KD: | C10: Trần Văn Phóng | D10: Điện thoại KD: | G10: 0866.98.93.99 | X10: =UPPER(LEFT(TRIM(IF(W6=0,"không đồng.",#REF!&" "&Y9&" "&#REF!&" "&Z9&" "&#REF!&" "&AA9&" "&#REF!&" "&AB9&" "&#REF!&" "&AC9&" "&#REF!&" "&AD9&" "&#REF!&" "&AE9&" "&#REF!&" "&AF9&" "&#REF!&" "&AG9&" "&#REF!&" "&AH9&" "&#REF!&" "&AI9&" "&#REF!&" "&AJ9)),1))&RIGHT(TRIM(IF(W6=0,"không đồng.",#REF!&" "&Y9&" "&#REF!&" "&Z9&" "&#REF!&" "&AA9&" "&#REF!&" "&AB9&" "&#REF!&" "&AC9&" "&#REF!&" "&AD9&" "&#REF!&" "&AE9&" "&#REF!&" "&AF9&" "&#REF!&" "&AG9&" "&#REF!&" "&AH9&" "&#REF!&" "&AI9&" "&#REF!&" "&AJ9)),LEN(TRIM(IF(W6=0,"không đồng.",#REF!&" "&Y9&" "&#REF!&" "&Z9&" "&#REF!&" "&AA9&" "&#REF!&" "&AB9&" "&#REF!&" "&AC9&" "&#REF!&" "&AD9&" "&#REF!&" "&AE9&" "&#REF!&" "&AF9&" "&#REF!&" "&AG9&" "&#REF!&" "&AH9&" "&#REF!&" "&AI9&" "&#REF!&" "&AJ9)))-1) -> Không đồng.
L12: Chèn dòng này
A13: Khách hàng nhận hàng lúc: …….... giờ …….. phút, ngày ….. tháng ….. năm 2026 | L13: Ghi chú: Khổ >600 tùy từng đơn hàng tính giá tương ứng khối lượng tôn xả cho hợp lý
A14: Người lập phiếu Người nhận hàng Lái xe Thủ kho BGĐ Nhà máy
A15: (ký, ghi rõ họ tên) (ký, ghi rõ họ tên) (ký, ghi rõ họ tên) (ký, ghi rõ họ tên) (ký, ghi rõ họ tên)
I21: =2.3+2.13+2.1+2.2 -> 8.73
